<testsuites>
    <testsuite name="TestTiti">
        <testcase classname="TestTiti"
            name="TestTiti.test1_withFailure">
            <failure type="example_with_luaunit.lua:99: expected: 2, actual: 1">
                <![CDATA[stack traceback:
	.\luaunit.lua:476: in function 'assertEquals'
	example_with_luaunit.lua:99: in function 'TestTiti.test1_withFailure'
	.\luaunit.lua:1432: in function <.\luaunit.lua:1432>
	[C]: in function 'xpcall'
	.\luaunit.lua:1432: in function 'protectedCall'
	.\luaunit.lua:1489: in function 'execOneFunction'
	.\luaunit.lua:1588: in function 'runSuiteByInstances'
	.\luaunit.lua:1641: in function 'runSuiteByNames'
	.\luaunit.lua:1717: in function 'runSuite'
	example_with_luaunit.lua:140: in main chunk
	[C]: in ?]]></failure>
        </testcase>
        <testcase classname="TestTiti"
            name="TestTiti.test2_withFailure">
            <failure type="example_with_luaunit.lua:108: expected: &quot;bof&quot;
actual: &quot;hop&quot;">
                <![CDATA[stack traceback:
	.\luaunit.lua:476: in function 'assertEquals'
	example_with_luaunit.lua:108: in function 'TestTiti.test2_withFailure'
	.\luaunit.lua:1432: in function <.\luaunit.lua:1432>
	[C]: in function 'xpcall'
	.\luaunit.lua:1432: in function 'protectedCall'
	.\luaunit.lua:1489: in function 'execOneFunction'
	.\luaunit.lua:1588: in function 'runSuiteByInstances'
	.\luaunit.lua:1641: in function 'runSuiteByNames'
	.\luaunit.lua:1717: in function 'runSuite'
	example_with_luaunit.lua:140: in main chunk
	[C]: in ?]]></failure>
        </testcase>
        <testcase classname="TestTiti"
            name="TestTiti.test3">
        </testcase>
    </testsuite>
    <testsuite name="TestToto">
        <testcase classname="TestToto"
            name="TestToto.test1_withFailure">
            <failure type="example_with_luaunit.lua:19: expected: 2, actual: 1">
                <![CDATA[stack traceback:
	.\luaunit.lua:476: in function 'assertEquals'
	example_with_luaunit.lua:19: in function 'TestToto.test1_withFailure'
	.\luaunit.lua:1432: in function <.\luaunit.lua:1432>
	[C]: in function 'xpcall'
	.\luaunit.lua:1432: in function 'protectedCall'
	.\luaunit.lua:1489: in function 'execOneFunction'
	.\luaunit.lua:1588: in function 'runSuiteByInstances'
	.\luaunit.lua:1641: in function 'runSuiteByNames'
	.\luaunit.lua:1717: in function 'runSuite'
	example_with_luaunit.lua:140: in main chunk
	[C]: in ?]]></failure>
        </testcase>
        <testcase classname="TestToto"
            name="TestToto.test2_withFailure">
            <failure type="example_with_luaunit.lua:28: expected: &quot;bof&quot;
actual: &quot;hop&quot;">
                <![CDATA[stack traceback:
	.\luaunit.lua:476: in function 'assertEquals'
	example_with_luaunit.lua:28: in function 'TestToto.test2_withFailure'
	.\luaunit.lua:1432: in function <.\luaunit.lua:1432>
	[C]: in function 'xpcall'
	.\luaunit.lua:1432: in function 'protectedCall'
	.\luaunit.lua:1489: in function 'execOneFunction'
	.\luaunit.lua:1588: in function 'runSuiteByInstances'
	.\luaunit.lua:1641: in function 'runSuiteByNames'
	.\luaunit.lua:1717: in function 'runSuite'
	example_with_luaunit.lua:140: in main chunk
	[C]: in ?]]></failure>
        </testcase>
        <testcase classname="TestToto"
            name="TestToto.test3">
        </testcase>
        <testcase classname="TestToto"
            name="TestToto.test4">
            <failure type="example_with_luaunit.lua:41: Received the not expected value: 1">
                <![CDATA[stack traceback:
	.\luaunit.lua:516: in function 'assertNotEquals'
	example_with_luaunit.lua:41: in function 'TestToto.test4'
	.\luaunit.lua:1432: in function <.\luaunit.lua:1432>
	[C]: in function 'xpcall'
	.\luaunit.lua:1432: in function 'protectedCall'
	.\luaunit.lua:1489: in function 'execOneFunction'
	.\luaunit.lua:1588: in function 'runSuiteByInstances'
	.\luaunit.lua:1641: in function 'runSuiteByNames'
	.\luaunit.lua:1717: in function 'runSuite'
	example_with_luaunit.lua:140: in main chunk
	[C]: in ?]]></failure>
        </testcase>
        <testcase classname="TestToto"
            name="TestToto.test5">
            <failure type="example_with_luaunit.lua:47: expected: false, actual: 1">
                <![CDATA[stack traceback:
	.\luaunit.lua:452: in function 'assertFalse'
	example_with_luaunit.lua:47: in function 'TestToto.test5'
	.\luaunit.lua:1432: in function <.\luaunit.lua:1432>
	[C]: in function 'xpcall'
	.\luaunit.lua:1432: in function 'protectedCall'
	.\luaunit.lua:1489: in function 'execOneFunction'
	.\luaunit.lua:1588: in function 'runSuiteByInstances'
	.\luaunit.lua:1641: in function 'runSuiteByNames'
	.\luaunit.lua:1717: in function 'runSuite'
	example_with_luaunit.lua:140: in main chunk
	[C]: in ?]]></failure>
        </testcase>
        <testcase classname="TestToto"
            name="TestToto.test6">
            <failure type="example_with_luaunit.lua:52: expected: true, actual: false">
                <![CDATA[stack traceback:
	.\luaunit.lua:446: in function 'assertTrue'
	example_with_luaunit.lua:52: in function 'TestToto.test6'
	.\luaunit.lua:1432: in function <.\luaunit.lua:1432>
	[C]: in function 'xpcall'
	.\luaunit.lua:1432: in function 'protectedCall'
	.\luaunit.lua:1489: in function 'execOneFunction'
	.\luaunit.lua:1588: in function 'runSuiteByInstances'
	.\luaunit.lua:1641: in function 'runSuiteByNames'
	.\luaunit.lua:1717: in function 'runSuite'
	example_with_luaunit.lua:140: in main chunk
	[C]: in ?]]></failure>
        </testcase>
        <testcase classname="TestToto"
            name="TestToto.test7">
            <failure type="example_with_luaunit.lua:58: expected: {1, 2, three=3}
actual: {1, 2}">
                <![CDATA[stack traceback:
	.\luaunit.lua:471: in function 'assertEquals'
	example_with_luaunit.lua:58: in function 'TestToto.test7'
	.\luaunit.lua:1432: in function <.\luaunit.lua:1432>
	[C]: in function 'xpcall'
	.\luaunit.lua:1432: in function 'protectedCall'
	.\luaunit.lua:1489: in function 'execOneFunction'
	.\luaunit.lua:1588: in function 'runSuiteByInstances'
	.\luaunit.lua:1641: in function 'runSuiteByNames'
	.\luaunit.lua:1717: in function 'runSuite'
	example_with_luaunit.lua:140: in main chunk
	[C]: in ?]]></failure>
        </testcase>
        <testcase classname="TestToto"
            name="TestToto.test8a">
            <failure type="example_with_luaunit.lua:76: Bouhouhoum error!">
                <![CDATA[stack traceback:
	example_with_luaunit.lua:76: in function 'funcWithError'
	example_with_luaunit.lua:63: in function 'TestToto.test8a'
	.\luaunit.lua:1432: in function <.\luaunit.lua:1432>
	[C]: in function 'xpcall'
	.\luaunit.lua:1432: in function 'protectedCall'
	.\luaunit.lua:1489: in function 'execOneFunction'
	.\luaunit.lua:1588: in function 'runSuiteByInstances'
	.\luaunit.lua:1641: in function 'runSuiteByNames'
	.\luaunit.lua:1717: in function 'runSuite'
	example_with_luaunit.lua:140: in main chunk
	[C]: in ?]]></failure>
        </testcase>
        <testcase classname="TestToto"
            name="TestToto.test8b">
            <failure type="example_with_luaunit.lua:76: Bouhouhoum error!">
                <![CDATA[stack traceback:
	example_with_luaunit.lua:76: in function 'funcWithError'
	example_with_luaunit.lua:72: in function 'funcWithFuncWithError'
	example_with_luaunit.lua:68: in function 'TestToto.test8b'
	.\luaunit.lua:1432: in function <.\luaunit.lua:1432>
	[C]: in function 'xpcall'
	.\luaunit.lua:1432: in function 'protectedCall'
	.\luaunit.lua:1489: in function 'execOneFunction'
	.\luaunit.lua:1588: in function 'runSuiteByInstances'
	.\luaunit.lua:1641: in function 'runSuiteByNames'
	.\luaunit.lua:1717: in function 'runSuite'
	example_with_luaunit.lua:140: in main chunk
	[C]: in ?]]></failure>
        </testcase>
    </testsuite>
    <testsuite name="[TestFunctions]">
        <testcase classname="[TestFunctions]"
            name="test1_withFailure">
            <failure type="example_with_luaunit.lua:124: assertion failed!">
                <![CDATA[stack traceback:
	example_with_luaunit.lua:124: in function 'test1_withFailure'
	.\luaunit.lua:1434: in function <.\luaunit.lua:1434>
	[C]: in function 'xpcall'
	.\luaunit.lua:1434: in function 'protectedCall'
	.\luaunit.lua:1489: in function 'execOneFunction'
	.\luaunit.lua:1577: in function 'runSuiteByInstances'
	.\luaunit.lua:1641: in function 'runSuiteByNames'
	.\luaunit.lua:1717: in function 'runSuite'
	example_with_luaunit.lua:140: in main chunk
	[C]: in ?]]></failure>
        </testcase>
        <testcase classname="[TestFunctions]"
            name="test2_withFailure">
            <failure type="example_with_luaunit.lua:130: assertion failed!">
                <![CDATA[stack traceback:
	example_with_luaunit.lua:130: in function 'test2_withFailure'
	.\luaunit.lua:1434: in function <.\luaunit.lua:1434>
	[C]: in function 'xpcall'
	.\luaunit.lua:1434: in function 'protectedCall'
	.\luaunit.lua:1489: in function 'execOneFunction'
	.\luaunit.lua:1577: in function 'runSuiteByInstances'
	.\luaunit.lua:1641: in function 'runSuiteByNames'
	.\luaunit.lua:1717: in function 'runSuite'
	example_with_luaunit.lua:140: in main chunk
	[C]: in ?]]></failure>
        </testcase>
        <testcase classname="[TestFunctions]"
            name="test3">
        </testcase>
    </testsuite>
</testsuites>
