Started on 01/09/15 00:13:12
>>>>>>>>> TestTiti
>>> TestTiti.test1_withFailure
TestTiti:setUp
some stuff test 1
example_with_luaunit.lua:99: expected: 2, actual: 1
Failed
TestTiti:tearDown
>>> TestTiti.test2_withFailure
TestTiti:setUp
some stuff test 2
example_with_luaunit.lua:108: expected: "bof"
actual: "hop"
Failed
TestTiti:tearDown
>>> TestTiti.test3
TestTiti:setUp
some stuff test 3
TestTiti:tearDown

>>>>>>>>> TestToto
>>> TestToto.test1_withFailure
some stuff test 1
example_with_luaunit.lua:19: expected: 2, actual: 1
Failed
>>> TestToto.test2_withFailure
some stuff test 2
example_with_luaunit.lua:28: expected: "bof"
actual: "hop"
Failed
>>> TestToto.test3
some stuff test 3
>>> TestToto.test4
some stuff test 4
example_with_luaunit.lua:41: Received the not expected value: 1
Failed
>>> TestToto.test5
some stuff test 5
example_with_luaunit.lua:47: expected: false, actual: 1
Failed
>>> TestToto.test6
some stuff test 6
example_with_luaunit.lua:52: expected: true, actual: false
Failed
>>> TestToto.test7
example_with_luaunit.lua:58: expected: {1, 2, three=3}
actual: {1, 2}
Failed
>>> TestToto.test8a
example_with_luaunit.lua:76: Bouhouhoum error!
Failed
>>> TestToto.test8b
example_with_luaunit.lua:76: Bouhouhoum error!
Failed

>>>>>>>>> [TestFunctions]
>>> test1_withFailure
example_with_luaunit.lua:124: assertion failed!
Failed
>>> test2_withFailure
example_with_luaunit.lua:130: assertion failed!
Failed
>>> test3

=========================================================
Failed tests:
-------------
>>> TestTiti.test1_withFailure failed
example_with_luaunit.lua:99: expected: 2, actual: 1
stack traceback:
	.\luaunit.lua:476: in function 'assertEquals'
	example_with_luaunit.lua:99: in function 'TestTiti.test1_withFailure'
	.\luaunit.lua:1432: in function <.\luaunit.lua:1432>
	[C]: in function 'xpcall'
	.\luaunit.lua:1432: in function 'protectedCall'
	.\luaunit.lua:1489: in function 'execOneFunction'
	.\luaunit.lua:1588: in function 'runSuiteByInstances'
	.\luaunit.lua:1641: in function 'runSuiteByNames'
	.\luaunit.lua:1717: in function 'runSuite'
	example_with_luaunit.lua:140: in main chunk
	[C]: in ?
>>> TestTiti.test2_withFailure failed
example_with_luaunit.lua:108: expected: "bof"
actual: "hop"
stack traceback:
	.\luaunit.lua:476: in function 'assertEquals'
	example_with_luaunit.lua:108: in function 'TestTiti.test2_withFailure'
	.\luaunit.lua:1432: in function <.\luaunit.lua:1432>
	[C]: in function 'xpcall'
	.\luaunit.lua:1432: in function 'protectedCall'
	.\luaunit.lua:1489: in function 'execOneFunction'
	.\luaunit.lua:1588: in function 'runSuiteByInstances'
	.\luaunit.lua:1641: in function 'runSuiteByNames'
	.\luaunit.lua:1717: in function 'runSuite'
	example_with_luaunit.lua:140: in main chunk
	[C]: in ?
>>> TestToto.test1_withFailure failed
example_with_luaunit.lua:19: expected: 2, actual: 1
stack traceback:
	.\luaunit.lua:476: in function 'assertEquals'
	example_with_luaunit.lua:19: in function 'TestToto.test1_withFailure'
	.\luaunit.lua:1432: in function <.\luaunit.lua:1432>
	[C]: in function 'xpcall'
	.\luaunit.lua:1432: in function 'protectedCall'
	.\luaunit.lua:1489: in function 'execOneFunction'
	.\luaunit.lua:1588: in function 'runSuiteByInstances'
	.\luaunit.lua:1641: in function 'runSuiteByNames'
	.\luaunit.lua:1717: in function 'runSuite'
	example_with_luaunit.lua:140: in main chunk
	[C]: in ?
>>> TestToto.test2_withFailure failed
example_with_luaunit.lua:28: expected: "bof"
actual: "hop"
stack traceback:
	.\luaunit.lua:476: in function 'assertEquals'
	example_with_luaunit.lua:28: in function 'TestToto.test2_withFailure'
	.\luaunit.lua:1432: in function <.\luaunit.lua:1432>
	[C]: in function 'xpcall'
	.\luaunit.lua:1432: in function 'protectedCall'
	.\luaunit.lua:1489: in function 'execOneFunction'
	.\luaunit.lua:1588: in function 'runSuiteByInstances'
	.\luaunit.lua:1641: in function 'runSuiteByNames'
	.\luaunit.lua:1717: in function 'runSuite'
	example_with_luaunit.lua:140: in main chunk
	[C]: in ?
>>> TestToto.test4 failed
example_with_luaunit.lua:41: Received the not expected value: 1
stack traceback:
	.\luaunit.lua:516: in function 'assertNotEquals'
	example_with_luaunit.lua:41: in function 'TestToto.test4'
	.\luaunit.lua:1432: in function <.\luaunit.lua:1432>
	[C]: in function 'xpcall'
	.\luaunit.lua:1432: in function 'protectedCall'
	.\luaunit.lua:1489: in function 'execOneFunction'
	.\luaunit.lua:1588: in function 'runSuiteByInstances'
	.\luaunit.lua:1641: in function 'runSuiteByNames'
	.\luaunit.lua:1717: in function 'runSuite'
	example_with_luaunit.lua:140: in main chunk
	[C]: in ?
>>> TestToto.test5 failed
example_with_luaunit.lua:47: expected: false, actual: 1
stack traceback:
	.\luaunit.lua:452: in function 'assertFalse'
	example_with_luaunit.lua:47: in function 'TestToto.test5'
	.\luaunit.lua:1432: in function <.\luaunit.lua:1432>
	[C]: in function 'xpcall'
	.\luaunit.lua:1432: in function 'protectedCall'
	.\luaunit.lua:1489: in function 'execOneFunction'
	.\luaunit.lua:1588: in function 'runSuiteByInstances'
	.\luaunit.lua:1641: in function 'runSuiteByNames'
	.\luaunit.lua:1717: in function 'runSuite'
	example_with_luaunit.lua:140: in main chunk
	[C]: in ?
>>> TestToto.test6 failed
example_with_luaunit.lua:52: expected: true, actual: false
stack traceback:
	.\luaunit.lua:446: in function 'assertTrue'
	example_with_luaunit.lua:52: in function 'TestToto.test6'
	.\luaunit.lua:1432: in function <.\luaunit.lua:1432>
	[C]: in function 'xpcall'
	.\luaunit.lua:1432: in function 'protectedCall'
	.\luaunit.lua:1489: in function 'execOneFunction'
	.\luaunit.lua:1588: in function 'runSuiteByInstances'
	.\luaunit.lua:1641: in function 'runSuiteByNames'
	.\luaunit.lua:1717: in function 'runSuite'
	example_with_luaunit.lua:140: in main chunk
	[C]: in ?
>>> TestToto.test7 failed
example_with_luaunit.lua:58: expected: {1, 2, three=3}
actual: {1, 2}
stack traceback:
	.\luaunit.lua:471: in function 'assertEquals'
	example_with_luaunit.lua:58: in function 'TestToto.test7'
	.\luaunit.lua:1432: in function <.\luaunit.lua:1432>
	[C]: in function 'xpcall'
	.\luaunit.lua:1432: in function 'protectedCall'
	.\luaunit.lua:1489: in function 'execOneFunction'
	.\luaunit.lua:1588: in function 'runSuiteByInstances'
	.\luaunit.lua:1641: in function 'runSuiteByNames'
	.\luaunit.lua:1717: in function 'runSuite'
	example_with_luaunit.lua:140: in main chunk
	[C]: in ?
>>> TestToto.test8a failed
example_with_luaunit.lua:76: Bouhouhoum error!
stack traceback:
	example_with_luaunit.lua:76: in function 'funcWithError'
	example_with_luaunit.lua:63: in function 'TestToto.test8a'
	.\luaunit.lua:1432: in function <.\luaunit.lua:1432>
	[C]: in function 'xpcall'
	.\luaunit.lua:1432: in function 'protectedCall'
	.\luaunit.lua:1489: in function 'execOneFunction'
	.\luaunit.lua:1588: in function 'runSuiteByInstances'
	.\luaunit.lua:1641: in function 'runSuiteByNames'
	.\luaunit.lua:1717: in function 'runSuite'
	example_with_luaunit.lua:140: in main chunk
	[C]: in ?
>>> TestToto.test8b failed
example_with_luaunit.lua:76: Bouhouhoum error!
stack traceback:
	example_with_luaunit.lua:76: in function 'funcWithError'
	example_with_luaunit.lua:72: in function 'funcWithFuncWithError'
	example_with_luaunit.lua:68: in function 'TestToto.test8b'
	.\luaunit.lua:1432: in function <.\luaunit.lua:1432>
	[C]: in function 'xpcall'
	.\luaunit.lua:1432: in function 'protectedCall'
	.\luaunit.lua:1489: in function 'execOneFunction'
	.\luaunit.lua:1588: in function 'runSuiteByInstances'
	.\luaunit.lua:1641: in function 'runSuiteByNames'
	.\luaunit.lua:1717: in function 'runSuite'
	example_with_luaunit.lua:140: in main chunk
	[C]: in ?
>>> test1_withFailure failed
example_with_luaunit.lua:124: assertion failed!
stack traceback:
	example_with_luaunit.lua:124: in function 'test1_withFailure'
	.\luaunit.lua:1434: in function <.\luaunit.lua:1434>
	[C]: in function 'xpcall'
	.\luaunit.lua:1434: in function 'protectedCall'
	.\luaunit.lua:1489: in function 'execOneFunction'
	.\luaunit.lua:1577: in function 'runSuiteByInstances'
	.\luaunit.lua:1641: in function 'runSuiteByNames'
	.\luaunit.lua:1717: in function 'runSuite'
	example_with_luaunit.lua:140: in main chunk
	[C]: in ?
>>> test2_withFailure failed
example_with_luaunit.lua:130: assertion failed!
stack traceback:
	example_with_luaunit.lua:130: in function 'test2_withFailure'
	.\luaunit.lua:1434: in function <.\luaunit.lua:1434>
	[C]: in function 'xpcall'
	.\luaunit.lua:1434: in function 'protectedCall'
	.\luaunit.lua:1489: in function 'execOneFunction'
	.\luaunit.lua:1577: in function 'runSuiteByInstances'
	.\luaunit.lua:1641: in function 'runSuiteByNames'
	.\luaunit.lua:1717: in function 'runSuite'
	example_with_luaunit.lua:140: in main chunk
	[C]: in ?

Success: 20% - 3 / 15, executed in 0.000 seconds
